<!DOCTYPE html>
<html lang="en">

<head>
    <meta charset="UTF-8" />
    <meta http-equiv="X-UA-Compatible" content="IE=edge" />
    <meta name="viewport" content="width=device-width, initial-scale=1.0" />
    <title>Document</title>
</head>

<body>
    <script>
    /* // Promise是一个内置的构造函数，通过new的方式来执行
        // 在执行时，需要传递一个函数executor function(执行器函数)同步执行
        // Promise 承诺
        // 参数：resolve(成功)，reject(失败)回调
        // pending(进行时) onFulfilled(成功) onRejected(失败)
        let oP = new Promise((resolve,reject) => {
            // 异步操作
            setTimeout(() => {
                Math.random * 100 > 60 ? resolve('ok') : reject('no');
            },1000)
        });

        // then 两个回调函数（成功，失败）
        // 异步执行
        // setTimeout()
        // 
        // 异步操作中分两种任务
        // 宏任务，会先放到队列中   微任务，微任务有优先 执行权
        // task queue 1         task queue 2
        //
        oP.then((val) => {
            console.log(val);
        },(reason) => {
            console.log(reason);
        })


        let oP = new Promise((resolve,reject) => {
            // 异步操作
            setTimeout(() => {
                Math.random() * 100 > 60 ? resolve('ok') : reject('no');
            },1000)
        }); */

    /* // 链式操作
        // 链式操作时，上一个不抛出错误时，那下一个then执行成功的函数
        
        // 返回值作为下一个then注册函数的执行参数

        // 返回值 Promise 对象

        // 当上一个then注册的函数抛出错误，下一个then的失败状态回调就会执行
        oP.then((val) => {
            console.log(val);
            // throw new Error('duyi');
            return new Promise((resolve,reject) => {
                resolve('newPromise ok');
            });
        },(reason) => {
            console.log(reason);
            return 30;
        }).then((val) => {
            console.log("okthen2:" + val)
        },(reason) => {
            console.log('nothen2:' + reason)
        }) */

    //回调地狱解决

    let oP = new Promise((resolve, reject) => {
        // throw new Error('duyi');
        resolve();
    });

    oP.then(() => {
        throw new Error('d')
    }, (reason) => {
        console.log(reason)
        //链式调用的时候如果写一个空then其实是相当于不存在，可以忽视
    }).then().then(() => {

    }).then(null, (reason) => {
        console.log(reason);
    }).catch((err) => {
        console.log(98, err);
        //在catch后面可以继续调用then
    }).then((val) => {
        console.log('catch after ok:' + val)
    }, (reason) => {
        console.log('catch after no:' + reason)
        //最终结束函数
    }).finally(() => {
        console.log('over')
    })
    </script>
</body>

</html>